Workbook

Sheet Convert
A1: รายงานปิดวัน ‎- ‎ยอดขายน้ำมันตามหน้าจ่าย‎
A3: รหัสสาขา : | B3: 101612 | G3: เริ่มต้น : | I3: 22/05/2568 | L3: วันเวลาที่พิมพ์ : | M3: 24/05/2568 07:04:35
A5: ชื่อสาขา : | B5: ห้างหุ้นส่วนสามัญนิติบุคคล อิสาณบริการ | G5: จนถึง : | I5: 22/05/2568 | L5: จัดทำโดย : | M5: นิตศรา คำใสสุข
A7: ชื่อน้ำมัน | C7: หน้าจ่าย | D7: มือจ่าย | E7: มิเตอร์เปิด | H7: มิเตอร์ปิด | J7: -ทดสอบ | L7: =ขาย(ลิตร) | N7: =ขาย(บาท)
A8: GASOHOL 95 | C8: 1 | D8: 1 | E8: 898043.92 | H8: 898411.96 | J8: 0 | L8: 368.04 | N8: 12240 | O8: 6A
A9: GASOHOL 91 | C9: 1 | D9: 2 | E9: 120488.52 | H9: 121097.56 | J9: 0 | L9: 609.04 | N9: 19994.3 | O9: 8A
A10: DIESEL | C10: 1 | D10: 3 | E10: 442986.21 | H10: 443657.8 | J10: 0 | L10: 671.59 | N10: 21820 | O10: 2A
A11: รวมหน้าจ่าย 1 | J11: 0 | L11: 1648.67 | N11: 54054.3
A12: GASOHOL 95 | C12: 2 | D12: 4 | E12: 349559.42 | H12: 349729.16 | J12: 0 | L12: 169.74 | N12: 5650 | O12: 6B
A13: GASOHOL 91 | C13: 2 | D13: 5 | E13: 532555.7 | H13: 532854.63 | J13: 0 | L13: 298.93 | N13: 9820 | O13: 8B
A14: DIESEL | C14: 2 | D14: 6 | E14: 529240.02 | H14: 529329.28 | J14: 0 | L14: 89.26 | N14: 2900 | O14: 2B
A15: รวมหน้าจ่าย 2 | J15: 0 | L15: 557.93 | N15: 18370
A16: GASOHOL 95 | C16: 3 | D16: 7 | E16: 147285.75 | H16: 147810.19 | J16: 0 | L16: 524.44 | N16: 17440 | O16: 6C
A17: Premium DIESEL | C17: 3 | D17: 8 | E17: 432029.16 | H17: 432056.14 | J17: 0 | L17: 26.98 | N17: 1200 | O17: 3A
A18: DIESEL | C18: 3 | D18: 9 | E18: 65763.43 | H18: 67637.42 | J18: 0 | L18: 1873.99 | N18: 60886.2 | O18: 1A
A19: รวมหน้าจ่าย 3 | J19: 0 | L19: 2425.41 | N19: 79526.2
A20: GASOHOL 95 | C20: 4 | D20: 10 | E20: 417774.76 | H20: 417839.16 | J20: 0 | L20: 64.4 | N20: 2136 | O20: 6D
A21: Premium DIESEL | C21: 4 | D21: 11 | E21: 177639.39 | H21: 177639.39 | J21: 0 | L21: 0 | N21: 0 | O21: 3B
A22: DIESEL | C22: 4 | D22: 12 | E22: 859430.27 | H22: 859808.85 | J22: 0 | L22: 378.58 | N22: 12300 | O22: 1B
A23: รวมหน้าจ่าย 4 | J23: 0 | L23: 442.98 | N23: 14436
A24: GASOHOL E20 | C24: 5 | D24: 13 | E24: 671031 | H24: 671207.34 | J24: 0 | L24: 176.34 | N24: 5470 | O24: 5A
A25: GASOHOL 91 | C25: 5 | D25: 14 | E25: 968661.58 | H25: 969134.13 | J25: 0 | L25: 472.55 | N25: 15506.5 | O25: 4A
A26: DIESEL | C26: 5 | D26: 15 | E26: 652171.23 | H26: 652824.35 | J26: 0 | L26: 653.12 | N26: 21220 | O26: 2C
A27: รวมหน้าจ่าย 5 | J27: 0 | L27: 1302.01 | N27: 42196.5
A28: GASOHOL E20 | C28: 6 | D28: 16 | E28: 135636.97 | H28: 135643.44 | J28: 0 | L28: 6.47 | N28: 200 | O28: 5B
A29: GASOHOL 91 | C29: 6 | D29: 17 | E29: 232438.39 | H29: 232526.97 | J29: 0 | L29: 88.58 | N29: 2910 | O29: 4B
A30: DIESEL | C30: 6 | D30: 18 | E30: 476760.38 | H30: 476785.33 | J30: 0 | L30: 24.95 | N30: 810.5 | O30: 2D
A31: รวมหน้าจ่าย 6 | J31: 0 | L31: 120 | N31: 3920.5
A32: GASOHOL E20 | C32: 7 | D32: 19 | E32: 26296.68 | H32: 26583.58 | J32: 0 | L32: 286.9 | N32: 8906.7 | O32: 5C
A33: Premium DIESEL | C33: 7 | D33: 20 | E33: 390645.65 | H33: 390645.65 | J33: 0 | L33: 0 | N33: 0 | O33: 3C
A34: DIESEL | C34: 7 | D34: 21 | E34: 421928.09 | H34: 423640.11 | J34: 0 | L34: 1712.02 | N34: 55623.7 | O34: 1C
A35: รวมหน้าจ่าย 7 | J35: 0 | L35: 1998.92 | N35: 64530.4
A36: GASOHOL E20 | C36: 8 | D36: 22 | E36: 237976.65 | H36: 238040.07 | J36: 0 | L36: 63.42 | N36: 1960 | O36: 5D
A37: Premium DIESEL | C37: 8 | D37: 23 | E37: 119466.7 | H37: 119466.7 | J37: 0 | L37: 0 | N37: 0 | O37: 3D
A38: DIESEL | C38: 8 | D38: 24 | E38: 627162.47 | H38: 627620.73 | J38: 0 | L38: 458.26 | N38: 14889 | O38: 1D
A39: รวมหน้าจ่าย 8 | J39: 0 | L39: 521.68 | N39: 16849
A40: GASOHOL E20 | C40: 9 | D40: 25 | E40: 381595.82 | H40: 381650.66 | J40: 0 | L40: 54.84 | N40: 1700 | O40: 10A
A41: GASOHOL 91 | C41: 9 | D41: 26 | E41: 717893.19 | H41: 718077.68 | J41: 0 | L41: 184.49 | N41: 6040 | O41: 8C
A42: DIESEL | C42: 9 | D42: 27 | E42: 457070.22 | H42: 457359.54 | J42: 0 | L42: 289.32 | N42: 9400 | O42: 2E
A43: รวมหน้าจ่าย 9 | J43: 0 | L43: 528.65 | N43: 17140
...

Sheet Petrol_price
A1: ชนิดน้ำมัน | B1: หลุม | C1: ราคาขายเฉลี่ย | D1: บันทึกราคาปลีกหน้าลาน | E1: Diff
A2: Premium Diesel | B2: 3 | C2: =if(sum(Dairy_Petrol!H17:H20)=0,0,round(Dairy_Petrol!J17,2)) -> 44.48 | D2: 44.49 | E2: =D2-C2 -> 0.01
A3: Premium Gasohal 95 | B3: 9 | C3: =if(sum(Dairy_Petrol!H41:H42)=0,0,round(Dairy_Petrol!J41,2)) -> 42.02 | D3: 41.69 | E3: =D3-C3 -> -0.33
A4: Diesel | B4: 1,2 | C4: =round(Dairy_Petrol!J3,2) -> 32.49 | D4: 32.49 | E4: =D4-C4 -> 0
A5: E85 | B5: 7 | C5: =round(Dairy_Petrol!J33,2) -> 29.44 | D5: 29.24 | E5: =D5-C5 -> -0.2
A6: E20 | B6: 5,10 | C6: =round(Dairy_Petrol!J23,2) -> 31.02 | D6: 30.89 | E6: =D6-C6 -> -0.13
A7: Gasohal 91 | B7: 4,8 | C7: =round(Dairy_Petrol!J21,2) -> 32.82 | D7: 32.73 | E7: =D7-C7 -> -0.09
A8: Gasohal 95 | B8: 6 | C8: =round(Dairy_Petrol!J27,2) -> 33.23 | D8: 33.1 | E8: =D8-C8 -> -0.13
E9: =IF(OR(E4<>0, E5<>0, E6<>0, E7<>0, E8<>0), "ปรับราคา", "") -> ปรับราคา

Sheet บันทึกลองลิตร
A2: หัวจ่าย | B2: บันทึกลองลิตรเพิ่ม
A3: 1A
A4: 1B
A5: 1C
A6: 1D
A7: 1E
A8: 1F
A9: 2A
A10: 2B
A11: 2C
A12: 2D
A13: 2E
A14: 2F
... A46: 10D

Sheet Dairy_Petrol
A1: วันที่ | B1: =Convert!I3 -> 22/05/2568 | C1: รายวันขาย
A2: หัวจ่าย | B2: มิเตอร์ยกมา | C2: มิเตอร์วันนี้ | D2: ลองลิตร | E2: ลองลิตรเพิ่ม | F2: ขาย | G2: มูลค่าขายใบกะ | H2: ขาย | I2: มูลค่าขายหน้าลาน | J2: ราคา/ลิตร(เฉลี่ยขาย) | K2: น้ำมัน | L2: ราคาป้าย | M2: จำนวนเงิน | N2: หมายเหตุ
A3: 1A | B3: {=round(xlookup(A3,Convert!O:O,Convert!E:E,"-"),1)} -> 65763.4 | C3: {=round(xlookup(A3,Convert!O:O,Convert!H:H,"-"),1)} -> 67637.4 | D3: {=XLOOKUP(A3,Convert!O:O,Convert!J:J,"-")} -> 0 | E3: ='บันทึกลองลิตร'!B3 | F3: =round(C3-B3-D3-E3,1) -> 1874 | G3: {=XLOOKUP(A3,Convert!O:O,Convert!N:N,"-")} -> 60886.2 | H3: {=XLOOKUP(A3,Convert!O:O,Convert!L:L,"-")} -> 1873.99 | I3: =H3*L$3 -> 60885.935 | J3: =sum(G3:G8)/sum(H3:H8) -> 32.490101 | K3: HSD | L3: =Petrol_price!D4 -> 32.49 | M3: =F3*$L$3 -> 60886.26
A4: 1B | B4: {=round(xlookup(A4,Convert!O:O,Convert!E:E,"-"),1)} -> 859430.3 | C4: {=round(xlookup(A4,Convert!O:O,Convert!H:H,"-"),1)} -> 859808.9 | D4: {=XLOOKUP(A4,Convert!O:O,Convert!J:J,"-")} -> 0 | E4: ='บันทึกลองลิตร'!B4 | F4: =round(C4-B4-D4-E4,1) -> 378.6 | G4: {=XLOOKUP(A4,Convert!O:O,Convert!N:N,"-")} -> 12300 | H4: {=XLOOKUP(A4,Convert!O:O,Convert!L:L,"-")} -> 378.58 | I4: =H4*L$3 -> 12300.064 | L4: " | M4: =F4*$L$3 -> 12300.714
A5: 1C | B5: {=round(xlookup(A5,Convert!O:O,Convert!E:E,"-"),1)} -> 421928.1 | C5: {=round(xlookup(A5,Convert!O:O,Convert!H:H,"-"),1)} -> 423640.1 | D5: {=XLOOKUP(A5,Convert!O:O,Convert!J:J,"-")} -> 0 | E5: ='บันทึกลองลิตร'!B5 | F5: =round(C5-B5-D5-E5,1) -> 1712 | G5: {=XLOOKUP(A5,Convert!O:O,Convert!N:N,"-")} -> 55623.7 | H5: {=XLOOKUP(A5,Convert!O:O,Convert!L:L,"-")} -> 1712.02 | I5: =H5*L$3 -> 55623.53 | L5: " | M5: =F5*$L$3 -> 55622.88
A6: 1D | B6: {=round(xlookup(A6,Convert!O:O,Convert!E:E,"-"),1)} -> 627162.5 | C6: {=round(xlookup(A6,Convert!O:O,Convert!H:H,"-"),1)} -> 627620.7 | D6: {=XLOOKUP(A6,Convert!O:O,Convert!J:J,"-")} -> 0 | E6: ='บันทึกลองลิตร'!B6 | F6: =round(C6-B6-D6-E6,1) -> 458.2 | G6: {=XLOOKUP(A6,Convert!O:O,Convert!N:N,"-")} -> 14889 | H6: {=XLOOKUP(A6,Convert!O:O,Convert!L:L,"-")} -> 458.26 | I6: =H6*L$3 -> 14888.867 | L6: " | M6: =F6*$L$3 -> 14886.918
A7: 1E | B7: {=round(xlookup(A7,Convert!O:O,Convert!E:E,"-"),1)} -> 785206.2 | C7: {=round(xlookup(A7,Convert!O:O,Convert!H:H,"-"),1)} -> 786496.5 | D7: {=XLOOKUP(A7,Convert!O:O,Convert!J:J,"-")} -> 0 | E7: ='บันทึกลองลิตร'!B7 | F7: =round(C7-B7-D7-E7,1) -> 1290.3 | G7: {=XLOOKUP(A7,Convert!O:O,Convert!N:N,"-")} -> 41922.5 | H7: {=XLOOKUP(A7,Convert!O:O,Convert!L:L,"-")} -> 1290.32 | I7: =H7*L$3 -> 41922.497 | L7: " | M7: =F7*$L$3 -> 41921.847
A8: 1F | B8: {=round(xlookup(A8,Convert!O:O,Convert!E:E,"-"),1)} -> 452661.3 | C8: {=round(xlookup(A8,Convert!O:O,Convert!H:H,"-"),1)} -> 452744.4 | D8: {=XLOOKUP(A8,Convert!O:O,Convert!J:J,"-")} -> 0 | E8: ='บันทึกลองลิตร'!B8 | F8: =round(C8-B8-D8-E8,1) -> 83.1 | G8: {=XLOOKUP(A8,Convert!O:O,Convert!N:N,"-")} -> 2700 | H8: {=XLOOKUP(A8,Convert!O:O,Convert!L:L,"-")} -> 83.1 | I8: =H8*L$3 -> 2699.919 | L8: " | M8: =F8*$L$3 -> 2699.919 | N8: =SUM(F3:F8) -> 5796.2
A9: 2A | B9: {=round(xlookup(A9,Convert!O:O,Convert!E:E,"-"),1)} -> 442986.2 | C9: {=round(xlookup(A9,Convert!O:O,Convert!H:H,"-"),1)} -> 443657.8 | D9: {=XLOOKUP(A9,Convert!O:O,Convert!J:J,"-")} -> 0 | E9: ='บันทึกลองลิตร'!B9 | F9: =round(C9-B9-D9-E9,1) -> 671.6 | G9: {=XLOOKUP(A9,Convert!O:O,Convert!N:N,"-")} -> 21820 | H9: {=XLOOKUP(A9,Convert!O:O,Convert!L:L,"-")} -> 671.59 | I9: =H9*L$9 -> 21819.959 | J9: =sum(G9:G16)/sum(H9:H16) -> 32.48995 | K9: HSD | L9: =Petrol_price!D4 -> 32.49 | M9: =F9*$L$9 -> 21820.284
A10: 2B | B10: {=round(xlookup(A10,Convert!O:O,Convert!E:E,"-"),1)} -> 529240 | C10: {=round(xlookup(A10,Convert!O:O,Convert!H:H,"-"),1)} -> 529329.3 | D10: {=XLOOKUP(A10,Convert!O:O,Convert!J:J,"-")} -> 0 | E10: ='บันทึกลองลิตร'!B10 | F10: =round(C10-B10-D10-E10,1) -> 89.3 | G10: {=XLOOKUP(A10,Convert!O:O,Convert!N:N,"-")} -> 2900 | H10: {=XLOOKUP(A10,Convert!O:O,Convert!L:L,"-")} -> 89.26 | I10: =H10*L$9 -> 2900.0574 | L10: " | M10: =F10*$L$9 -> 2901.357
A11: 2C | B11: {=round(xlookup(A11,Convert!O:O,Convert!E:E,"-"),1)} -> 652171.2 | C11: {=round(xlookup(A11,Convert!O:O,Convert!H:H,"-"),1)} -> 652824.4 | D11: {=XLOOKUP(A11,Convert!O:O,Convert!J:J,"-")} -> 0 | E11: ='บันทึกลองลิตร'!B11 | F11: =round(C11-B11-D11-E11,1) -> 653.2 | G11: {=XLOOKUP(A11,Convert!O:O,Convert!N:N,"-")} -> 21220 | H11: {=XLOOKUP(A11,Convert!O:O,Convert!L:L,"-")} -> 653.12 | I11: =H11*L$9 -> 21219.869 | L11: " | M11: =F11*$L$9 -> 21222.468
A12: 2D | B12: {=round(xlookup(A12,Convert!O:O,Convert!E:E,"-"),1)} -> 476760.4 | C12: {=round(xlookup(A12,Convert!O:O,Convert!H:H,"-"),1)} -> 476785.3 | D12: {=XLOOKUP(A12,Convert!O:O,Convert!J:J,"-")} -> 0 | E12: ='บันทึกลองลิตร'!B12 | F12: =round(C12-B12-D12-E12,1) -> 24.9 | G12: {=XLOOKUP(A12,Convert!O:O,Convert!N:N,"-")} -> 810.5 | H12: {=XLOOKUP(A12,Convert!O:O,Convert!L:L,"-")} -> 24.95 | I12: =H12*L$9 -> 810.6255 | L12: " | M12: =F12*$L$9 -> 809.001
A13: 2E | B13: {=round(xlookup(A13,Convert!O:O,Convert!E:E,"-"),1)} -> 457070.2 | C13: {=round(xlookup(A13,Convert!O:O,Convert!H:H,"-"),1)} -> 457359.5 | D13: {=XLOOKUP(A13,Convert!O:O,Convert!J:J,"-")} -> 0 | E13: ='บันทึกลองลิตร'!B13 | F13: =round(C13-B13-D13-E13,1) -> 289.3 | G13: {=XLOOKUP(A13,Convert!O:O,Convert!N:N,"-")} -> 9400 | H13: {=XLOOKUP(A13,Convert!O:O,Convert!L:L,"-")} -> 289.32 | I13: =H13*L$9 -> 9400.0068 | L13: " | M13: =F13*$L$9 -> 9399.357
A14: 2F | B14: {=round(xlookup(A14,Convert!O:O,Convert!E:E,"-"),1)} -> 367409.7 | C14: {=round(xlookup(A14,Convert!O:O,Convert!H:H,"-"),1)} -> 367478.4 | D14: {=XLOOKUP(A14,Convert!O:O,Convert!J:J,"-")} -> 0 | E14: ='บันทึกลองลิตร'!B14 | F14: =round(C14-B14-D14-E14,1) -> 68.7 | G14: {=XLOOKUP(A14,Convert!O:O,Convert!N:N,"-")} -> 2230 | H14: {=XLOOKUP(A14,Convert!O:O,Convert!L:L,"-")} -> 68.64 | I14: =H14*L$9 -> 2230.1136 | L14: " | M14: =F14*$L$9 -> 2232.063
A15: 2G | B15: {=round(xlookup(A15,Convert!O:O,Convert!E:E,"-"),1)} -> 467032 | C15: {=round(xlookup(A15,Convert!O:O,Convert!H:H,"-"),1)} -> 467535.6 | D15: {=XLOOKUP(A15,Convert!O:O,Convert!J:J,"-")} -> 0 | E15: ='บันทึกลองลิตร'!B15 | F15: =round(C15-B15-D15-E15,1) -> 503.6 | G15: {=XLOOKUP(A15,Convert!O:O,Convert!N:N,"-")} -> 16361.3 | H15: {=XLOOKUP(A15,Convert!O:O,Convert!L:L,"-")} -> 503.58 | I15: =H15*L$9 -> 16361.314 | L15: " | M15: =F15*$L$9 -> 16361.964
A16: 2H | B16: {=round(xlookup(A16,Convert!O:O,Convert!E:E,"-"),1)} -> 172619.3 | C16: {=round(xlookup(A16,Convert!O:O,Convert!H:H,"-"),1)} -> 173219.3 | D16: {=XLOOKUP(A16,Convert!O:O,Convert!J:J,"-")} -> 0 | E16: ='บันทึกลองลิตร'!B16 | F16: =round(C16-B16-D16-E16,1) -> 600 | G16: {=XLOOKUP(A16,Convert!O:O,Convert!N:N,"-")} -> 19494 | H16: {=XLOOKUP(A16,Convert!O:O,Convert!L:L,"-")} -> 600 | I16: =H16*L$9 -> 19494 | L16: " | M16: =F16*$L$9 -> 19494 | N16: =sum(F9:F16) -> 2900.6
A17: 3A | B17: {=round(xlookup(A17,Convert!O:O,Convert!E:E,"-"),1)} -> 432029.2 | C17: {=round(xlookup(A17,Convert!O:O,Convert!H:H,"-"),1)} -> 432056.1 | D17: {=XLOOKUP(A17,Convert!O:O,Convert!J:J,"-")} -> 0 | E17: ='บันทึกลองลิตร'!B17 | F17: =round(C17-B17-D17-E17,1) -> 26.9 | G17: {=XLOOKUP(A17,Convert!O:O,Convert!N:N,"-")} -> 1200 | H17: {=XLOOKUP(A17,Convert!O:O,Convert!L:L,"-")} -> 26.98 | I17: =H17*L$17 -> 1200.3402 | J17: =sum(G17:G20)/sum(H17:H20) -> 44.477391 | K17: HSP | L17: =Petrol_price!D2 -> 44.49 | M17: =F17*$L$17 -> 1196.781
A18: 3B | B18: {=round(xlookup(A18,Convert!O:O,Convert!E:E,"-"),1)} -> 177639.4 | C18: {=round(xlookup(A18,Convert!O:O,Convert!H:H,"-"),1)} -> 177639.4 | D18: {=XLOOKUP(A18,Convert!O:O,Convert!J:J,"-")} -> 0 | E18: ='บันทึกลองลิตร'!B18 | F18: =round(C18-B18-D18-E18,1) -> 0 | G18: {=XLOOKUP(A18,Convert!O:O,Convert!N:N,"-")} -> 0 | H18: {=XLOOKUP(A18,Convert!O:O,Convert!L:L,"-")} -> 0 | I18: =H18*L$17 -> 0 | L18: " | M18: =F18*$L$17 -> 0
A19: 3C | B19: {=round(xlookup(A19,Convert!O:O,Convert!E:E,"-"),1)} -> 390645.7 | C19: {=round(xlookup(A19,Convert!O:O,Convert!H:H,"-"),1)} -> 390645.7 | D19: {=XLOOKUP(A19,Convert!O:O,Convert!J:J,"-")} -> 0 | E19: ='บันทึกลองลิตร'!B19 | F19: =round(C19-B19-D19-E19,1) -> 0 | G19: {=XLOOKUP(A19,Convert!O:O,Convert!N:N,"-")} -> 0 | H19: {=XLOOKUP(A19,Convert!O:O,Convert!L:L,"-")} -> 0 | I19: =H19*L$17 -> 0 | L19: " | M19: =F19*$L$17 -> 0
A20: 3D | B20: {=round(xlookup(A20,Convert!O:O,Convert!E:E,"-"),1)} -> 119466.7 | C20: {=round(xlookup(A20,Convert!O:O,Convert!H:H,"-"),1)} -> 119466.7 | D20: {=XLOOKUP(A20,Convert!O:O,Convert!J:J,"-")} -> 0 | E20: ='บันทึกลองลิตร'!B20 | F20: =round(C20-B20-D20-E20,1) -> 0 | G20: {=XLOOKUP(A20,Convert!O:O,Convert!N:N,"-")} -> 0 | H20: {=XLOOKUP(A20,Convert!O:O,Convert!L:L,"-")} -> 0 | I20: =H20*L$17 -> 0 | L20: " | M20: =F20*$L$17 -> 0 | N20: =sum(F17:F20) -> 26.9
A21: 4A | B21: {=round(xlookup(A21,Convert!O:O,Convert!E:E,"-"),1)} -> 968661.6 | C21: {=round(xlookup(A21,Convert!O:O,Convert!H:H,"-"),1)} -> 969134.1 | D21: {=XLOOKUP(A21,Convert!O:O,Convert!J:J,"-")} -> 0 | E21: ='บันทึกลองลิตร'!B21 | F21: =round(C21-B21-D21-E21,1) -> 472.5 | G21: {=XLOOKUP(A21,Convert!O:O,Convert!N:N,"-")} -> 15506.5 | H21: {=XLOOKUP(A21,Convert!O:O,Convert!L:L,"-")} -> 472.55 | I21: =H21*L$21 -> 15466.561 | J21: =sum(G21:G22)/sum(H21:H22) -> 32.82038 | K21: G91 | L21: =Petrol_price!D7 -> 32.73 | M21: =F21*$L$21 -> 15464.925
A22: 4B | B22: {=round(xlookup(A22,Convert!O:O,Convert!E:E,"-"),1)} -> 232438.4 | C22: {=round(xlookup(A22,Convert!O:O,Convert!H:H,"-"),1)} -> 232527 | D22: {=XLOOKUP(A22,Convert!O:O,Convert!J:J,"-")} -> 0 | E22: ='บันทึกลองลิตร'!B22 | F22: =round(C22-B22-D22-E22,1) -> 88.6 | G22: {=XLOOKUP(A22,Convert!O:O,Convert!N:N,"-")} -> 2910 | H22: {=XLOOKUP(A22,Convert!O:O,Convert!L:L,"-")} -> 88.58 | I22: =H22*L$21 -> 2899.2234 | L22: " | M22: =F22*$L$21 -> 2899.878 | N22: =sum(F21:F22) -> 561.1
A23: 5A | B23: {=round(xlookup(A23,Convert!O:O,Convert!E:E,"-"),1)} -> 671031 | C23: {=round(xlookup(A23,Convert!O:O,Convert!H:H,"-"),1)} -> 671207.3 | D23: {=XLOOKUP(A23,Convert!O:O,Convert!J:J,"-")} -> 0 | E23: ='บันทึกลองลิตร'!B23 | F23: =round(C23-B23-D23-E23,1) -> 176.3 | G23: {=XLOOKUP(A23,Convert!O:O,Convert!N:N,"-")} -> 5470 | H23: {=XLOOKUP(A23,Convert!O:O,Convert!L:L,"-")} -> 176.34 | I23: =H23*L$23 -> 5447.1426 | J23: =sum(G23:G26)/sum(H23:H26) -> 31.018138 | K23: E20 | L23: =Petrol_price!D6 -> 30.89 | M23: =F23*$L$23 -> 5445.907
A24: 5B | B24: {=round(xlookup(A24,Convert!O:O,Convert!E:E,"-"),1)} -> 135637 | C24: {=round(xlookup(A24,Convert!O:O,Convert!H:H,"-"),1)} -> 135643.4 | D24: {=XLOOKUP(A24,Convert!O:O,Convert!J:J,"-")} -> 0 | E24: ='บันทึกลองลิตร'!B24 | F24: =round(C24-B24-D24-E24,1) -> 6.4 | G24: {=XLOOKUP(A24,Convert!O:O,Convert!N:N,"-")} -> 200 | H24: {=XLOOKUP(A24,Convert!O:O,Convert!L:L,"-")} -> 6.47 | I24: =H24*L$23 -> 199.8583 | L24: " | M24: =F24*$L$23 -> 197.696
A25: 5C | B25: {=round(xlookup(A25,Convert!O:O,Convert!E:E,"-"),1)} -> 26296.7 | C25: {=round(xlookup(A25,Convert!O:O,Convert!H:H,"-"),1)} -> 26583.6 | D25: {=XLOOKUP(A25,Convert!O:O,Convert!J:J,"-")} -> 0 | E25: ='บันทึกลองลิตร'!B25 | F25: =round(C25-B25-D25-E25,1) -> 286.9 | G25: {=XLOOKUP(A25,Convert!O:O,Convert!N:N,"-")} -> 8906.7 | H25: {=XLOOKUP(A25,Convert!O:O,Convert!L:L,"-")} -> 286.9 | I25: =H25*L$23 -> 8862.341 | L25: " | M25: =F25*$L$23 -> 8862.341
A26: 5D | B26: {=round(xlookup(A26,Convert!O:O,Convert!E:E,"-"),1)} -> 237976.7 | C26: {=round(xlookup(A26,Convert!O:O,Convert!H:H,"-"),1)} -> 238040.1 | D26: {=XLOOKUP(A26,Convert!O:O,Convert!J:J,"-")} -> 0 | E26: ='บันทึกลองลิตร'!B26 | F26: =round(C26-B26-D26-E26,1) -> 63.4 | G26: {=XLOOKUP(A26,Convert!O:O,Convert!N:N,"-")} -> 1960 | H26: {=XLOOKUP(A26,Convert!O:O,Convert!L:L,"-")} -> 63.42 | I26: =H26*L$23 -> 1959.0438 | L26: " | M26: =F26*$L$23 -> 1958.426 | N26: =sum(F23:F26) -> 533
A27: 6A | B27: {=round(xlookup(A27,Convert!O:O,Convert!E:E,"-"),1)} -> 898043.9 | C27: {=round(xlookup(A27,Convert!O:O,Convert!H:H,"-"),1)} -> 898412 | D27: {=XLOOKUP(A27,Convert!O:O,Convert!J:J,"-")} -> 0 | E27: ='บันทึกลองลิตร'!B27 | F27: =round(C27-B27-D27-E27,1) -> 368.1 | G27: {=XLOOKUP(A27,Convert!O:O,Convert!N:N,"-")} -> 12240 | H27: {=XLOOKUP(A27,Convert!O:O,Convert!L:L,"-")} -> 368.04 | I27: =H27*L$27 -> 12182.124 | J27: =sum(G27:G32)/sum(H27:H32) -> 33.233118 | K27: G95 | L27: =Petrol_price!D8 -> 33.1 | M27: =F27*$L$27 -> 12184.11
A28: 6B | B28: {=round(xlookup(A28,Convert!O:O,Convert!E:E,"-"),1)} -> 349559.4 | C28: {=round(xlookup(A28,Convert!O:O,Convert!H:H,"-"),1)} -> 349729.2 | D28: {=XLOOKUP(A28,Convert!O:O,Convert!J:J,"-")} -> 0 | E28: ='บันทึกลองลิตร'!B28 | F28: =round(C28-B28-D28-E28,1) -> 169.8 | G28: {=XLOOKUP(A28,Convert!O:O,Convert!N:N,"-")} -> 5650 | H28: {=XLOOKUP(A28,Convert!O:O,Convert!L:L,"-")} -> 169.74 | I28: =H28*L$27 -> 5618.394 | L28: " | M28: =F28*$L$27 -> 5620.38
A29: 6C | B29: {=round(xlookup(A29,Convert!O:O,Convert!E:E,"-"),1)} -> 147285.8 | C29: {=round(xlookup(A29,Convert!O:O,Convert!H:H,"-"),1)} -> 147810.2 | D29: {=XLOOKUP(A29,Convert!O:O,Convert!J:J,"-")} -> 0 | E29: ='บันทึกลองลิตร'!B29 | F29: =round(C29-B29-D29-E29,1) -> 524.4 | G29: {=XLOOKUP(A29,Convert!O:O,Convert!N:N,"-")} -> 17440 | H29: {=XLOOKUP(A29,Convert!O:O,Convert!L:L,"-")} -> 524.44 | I29: =H29*L$27 -> 17358.964 | L29: " | M29: =F29*$L$27 -> 17357.64
A30: 6D | B30: {=round(xlookup(A30,Convert!O:O,Convert!E:E,"-"),1)} -> 417774.8 | C30: {=round(xlookup(A30,Convert!O:O,Convert!H:H,"-"),1)} -> 417839.2 | D30: {=XLOOKUP(A30,Convert!O:O,Convert!J:J,"-")} -> 0 | E30: ='บันทึกลองลิตร'!B30 | F30: =round(C30-B30-D30-E30,1) -> 64.4 | G30: {=XLOOKUP(A30,Convert!O:O,Convert!N:N,"-")} -> 2136 | H30: {=XLOOKUP(A30,Convert!O:O,Convert!L:L,"-")} -> 64.4 | I30: =H30*L$27 -> 2131.64 | L30: " | M30: =F30*$L$27 -> 2131.64
A31: 6E | B31: {=round(xlookup(A31,Convert!O:O,Convert!E:E,"-"),1)} -> 906948.3 | C31: {=round(xlookup(A31,Convert!O:O,Convert!H:H,"-"),1)} -> 907159 | D31: {=XLOOKUP(A31,Convert!O:O,Convert!J:J,"-")} -> 0 | E31: ='บันทึกลองลิตร'!B31 | F31: =round(C31-B31-D31-E31,1) -> 210.7 | G31: {=XLOOKUP(A31,Convert!O:O,Convert!N:N,"-")} -> 6981.5 | H31: {=XLOOKUP(A31,Convert!O:O,Convert!L:L,"-")} -> 210.76 | I31: =H31*L$27 -> 6976.156 | L31: " | M31: =F31*$L$27 -> 6974.17
A32: 6F | B32: {=round(xlookup(A32,Convert!O:O,Convert!E:E,"-"),1)} -> 317583.7 | C32: {=round(xlookup(A32,Convert!O:O,Convert!H:H,"-"),1)} -> 317618.3 | D32: {=XLOOKUP(A32,Convert!O:O,Convert!J:J,"-")} -> 0 | E32: ='บันทึกลองลิตร'!B32 | F32: =round(C32-B32-D32-E32,1) -> 34.6 | G32: {=XLOOKUP(A32,Convert!O:O,Convert!N:N,"-")} -> 1150 | H32: {=XLOOKUP(A32,Convert!O:O,Convert!L:L,"-")} -> 34.67 | I32: =H32*L$27 -> 1147.577 | L32: " | M32: =F32*$L$27 -> 1145.26 | N32: =sum(F27:F32) -> 1372
A33: 7A | B33: {=round(xlookup(A33,Convert!O:O,Convert!E:E,"-"),1)} -> 211870.9 | C33: {=round(xlookup(A33,Convert!O:O,Convert!H:H,"-"),1)} -> 211907.5 | D33: {=XLOOKUP(A33,Convert!O:O,Convert!J:J,"-")} -> 0 | E33: ='บันทึกลองลิตร'!B33 | F33: =round(C33-B33-D33-E33,1) -> 36.6 | G33: {=XLOOKUP(A33,Convert!O:O,Convert!N:N,"-")} -> 1080 | H33: {=XLOOKUP(A33,Convert!O:O,Convert!L:L,"-")} -> 36.57 | I33: =H33*L$33 -> 1069.3068 | J33: =sum(G33:G36)/sum(H33:H36) -> 29.443642 | K33: E85 | L33: =Petrol_price!D5 -> 29.24 | M33: =F33*$L$33 -> 1070.184
A34: 7B | B34: {=round(xlookup(A34,Convert!O:O,Convert!E:E,"-"),1)} -> 55508.7 | C34: {=round(xlookup(A34,Convert!O:O,Convert!H:H,"-"),1)} -> 55510.4 | D34: {=XLOOKUP(A34,Convert!O:O,Convert!J:J,"-")} -> 0 | E34: ='บันทึกลองลิตร'!B34 | F34: =round(C34-B34-D34-E34,1) -> 1.7 | G34: {=XLOOKUP(A34,Convert!O:O,Convert!N:N,"-")} -> 50 | H34: {=XLOOKUP(A34,Convert!O:O,Convert!L:L,"-")} -> 1.69 | I34: =H34*L$33 -> 49.4156 | L34: " | M34: =F34*$L$33 -> 49.708
A35: 7C | B35: {=round(xlookup(A35,Convert!O:O,Convert!E:E,"-"),1)} -> 226061.5 | C35: {=round(xlookup(A35,Convert!O:O,Convert!H:H,"-"),1)} -> 226078.6 | D35: {=XLOOKUP(A35,Convert!O:O,Convert!J:J,"-")} -> 0 | E35: ='บันทึกลองลิตร'!B35 | F35: =round(C35-B35-D35-E35,1) -> 17.1 | G35: {=XLOOKUP(A35,Convert!O:O,Convert!N:N,"-")} -> 500 | H35: {=XLOOKUP(A35,Convert!O:O,Convert!L:L,"-")} -> 17.1 | I35: =H35*L$33 -> 500.004 | L35: " | M35: =F35*$L$33 -> 500.004
A36: 7D | B36: {=round(xlookup(A36,Convert!O:O,Convert!E:E,"-"),1)} -> 39325.3 | C36: {=round(xlookup(A36,Convert!O:O,Convert!H:H,"-"),1)} -> 39325.3 | D36: {=XLOOKUP(A36,Convert!O:O,Convert!J:J,"-")} -> 0 | E36: ='บันทึกลองลิตร'!B36 | F36: =round(C36-B36-D36-E36,1) -> 0 | G36: {=XLOOKUP(A36,Convert!O:O,Convert!N:N,"-")} -> 0 | H36: {=XLOOKUP(A36,Convert!O:O,Convert!L:L,"-")} -> 0 | I36: =H36*L$33 -> 0 | L36: " | M36: =F36*$L$33 -> 0 | N36: =sum(F33:F36) -> 55.4
A37: 8A | B37: {=round(xlookup(A37,Convert!O:O,Convert!E:E,"-"),1)} -> 120488.5 | C37: {=round(xlookup(A37,Convert!O:O,Convert!H:H,"-"),1)} -> 121097.6 | D37: {=XLOOKUP(A37,Convert!O:O,Convert!J:J,"-")} -> 0 | E37: ='บันทึกลองลิตร'!B37 | F37: =round(C37-B37-D37-E37,1) -> 609.1 | G37: {=XLOOKUP(A37,Convert!O:O,Convert!N:N,"-")} -> 19994.3 | H37: {=XLOOKUP(A37,Convert!O:O,Convert!L:L,"-")} -> 609.04 | I37: =H37*L$37 -> 19933.879 | J37: =sum(G37:G40)/sum(H37:H40) -> 32.820301 | K37: G91 | L37: =Petrol_price!D7 -> 32.73 | M37: =F37*$L$37 -> 19935.843
A38: 8B | B38: {=round(xlookup(A38,Convert!O:O,Convert!E:E,"-"),1)} -> 532555.7 | C38: {=round(xlookup(A38,Convert!O:O,Convert!H:H,"-"),1)} -> 532854.6 | D38: {=XLOOKUP(A38,Convert!O:O,Convert!J:J,"-")} -> 0 | E38: ='บันทึกลองลิตร'!B38 | F38: =round(C38-B38-D38-E38,1) -> 298.9 | G38: {=XLOOKUP(A38,Convert!O:O,Convert!N:N,"-")} -> 9820 | H38: {=XLOOKUP(A38,Convert!O:O,Convert!L:L,"-")} -> 298.93 | I38: =H38*L$37 -> 9783.9789 | L38: " | M38: =F38*$L$37 -> 9782.997
A39: 8C | B39: {=round(xlookup(A39,Convert!O:O,Convert!E:E,"-"),1)} -> 717893.2 | C39: {=round(xlookup(A39,Convert!O:O,Convert!H:H,"-"),1)} -> 718077.7 | D39: {=XLOOKUP(A39,Convert!O:O,Convert!J:J,"-")} -> 0 | E39: ='บันทึกลองลิตร'!B39 | F39: =round(C39-B39-D39-E39,1) -> 184.5 | G39: {=XLOOKUP(A39,Convert!O:O,Convert!N:N,"-")} -> 6040 | H39: {=XLOOKUP(A39,Convert!O:O,Convert!L:L,"-")} -> 184.49 | I39: =H39*L$37 -> 6038.3577 | L39: " | M39: =F39*$L$37 -> 6038.685
A40: 8D | B40: {=round(xlookup(A40,Convert!O:O,Convert!E:E,"-"),1)} -> 218461.6 | C40: {=round(xlookup(A40,Convert!O:O,Convert!H:H,"-"),1)} -> 218469.2 | D40: {=XLOOKUP(A40,Convert!O:O,Convert!J:J,"-")} -> 0 | E40: ='บันทึกลองลิตร'!B40 | F40: =round(C40-B40-D40-E40,1) -> 7.6 | G40: {=XLOOKUP(A40,Convert!O:O,Convert!N:N,"-")} -> 250 | H40: {=XLOOKUP(A40,Convert!O:O,Convert!L:L,"-")} -> 7.6 | I40: =H40*L$37 -> 248.748 | L40: " | M40: =F40*$L$37 -> 248.748 | N40: =sum(F37:F40) -> 1100.1
...
